Workbook

Sheet Link To Excel
A3: TOTAL 2025 Beer/Food Pairings DATA
A5: NOVEMBER 2025 Pairings DATA

Sheet Kids Eat Free Data Columns
A1: Kids eat Free (Saturday) 5-9 PM | D1: Saturdays 5-9 PM 2024
A2: 45661 | B2: 517.5 | D2: 45297 | E2: 362
A3: 45668 | B3: 621 | D3: 45304 | E3: 488.5
A4: 45675 | B4: 571.5 | D4: 45311 | E4: 564.5
A5: 45682 | B5: 583.5 | D5: 45318 | E5: 565.5
A6: 45689 | B6: 616.5 | D6: 45325 | E6: 621.5
A7: 45696 | B7: 466 | D7: 45332 | E7: 516.5
A8: 45703 | B8: 926 | D8: 45339 | E8: 1247
A9: 45710 | B9: 912 | D9: 45346 | E9: 549
A10: 45717 | B10: 805.5 | D10: 45353 | E10: 923.5
A11: 45724 | B11: 783 | D11: 45360 | E11: 743.5
A12: 45731 | B12: 1286 | D12: 45367 | E12: 761
A13: 45738 | B13: 1690.5 | D13: 45374 | E13: 1183.5
... A41: 45934 | B41: 1098.5 | D41: 45570 | E41: 665
A46: Average | B46: =AVERAGE(B2:B41) -> 785.1125 | D46: Average | E46: =AVERAGE(E2:E41) -> 720.975

Sheet Trivia Nights Sales Data
F1: Thursday (6-9 PM 2024) | Q1: Thursday (6-9 PM 2024)
F2: 45295 | G2: 470.5 | M2: Month | N2: Sales 2025 | O2: Sales 2024 | Q2: 45295 | R2: 470.5
B3: Date | C3: Trivia Night (Th 6-9 PM 2025) | F3: 45302 | G3: 263.5 | M3: Jan | N3: =2751.5 -> 2751.5 | O3: 1379.5 | Q3: 45302 | R3: 263.5
B4: 45659 | C4: 493.5 | F4: 45309 | G4: 213 | M4: Feb | N4: 3002.5 | O4: 2575 | Q4: 45309 | R4: 213
B5: 45666 | C5: 520.5 | F5: 45316 | G5: 432.5 | M5: Mar | N5: 2092.5 | O5: 2234 | Q5: 45316 | R5: 432.5
B6: 45673 | C6: 601 | F6: 45323 | G6: 533.5 | M6: Apr | N6: 3387.5 | O6: 2881 | Q6: 45323 | R6: 533.5
B7: 45680 | C7: 682.5 | F7: 45330 | G7: 355 | M7: May | N7: 3672.5 | O7: 3543 | Q7: 45330 | R7: 355
B8: 45687 | C8: 454 | F8: 45337 | G8: 552.5 | M8: June | N8: 2818 | O8: 1520.5 | Q8: 45337 | R8: 552.5
B9: 45694 | C9: 448.5 | F9: 45344 | G9: 540 | M9: July | N9: 3062 | O9: 1401.5 | Q9: 45344 | R9: 540
B10: 45701 | C10: 786 | F10: 45351 | G10: 594 | M10: Aug | N10: 2187.5 | O10: 2031.5 | Q10: 45351 | R10: 594
B11: 45708 | C11: 854.5 | F11: 45358 | G11: 512 | M11: Sep | N11: 1777.5 | O11: 2559.5 | Q11: 45358 | R11: 512
B12: 45715 | C12: 913.5 | F12: 45365 | G12: 864 | M12: Oct | N12: 789.5 | O12: 517 | Q12: 45365 | R12: 864
B13: 45722 | C13: 634 | F13: 45372 | G13: 533 | Q13: 45372 | R13: 533
B14: 45729 | C14: 388 | F14: 45379 | G14: 325 | Q14: 45379 | R14: 325
B15: 45736 | C15: 530 | F15: 45386 | G15: 581 | Q15: 45386 | R15: 581
B16: 45743 | C16: 540.5 | F16: 45393 | G16: 679 | Q16: 45393 | R16: 679
B17: 45750 | C17: 790 | F17: 45400 | G17: 743 | Q17: 45400 | R17: 743
B18: 45757 | C18: 727 | F18: 45407 | G18: 878 | Q18: 45407 | R18: 878
B19: 45764 | C19: 1024 | F19: 45414 | G19: 586 | Q19: 45414 | R19: 586
B20: 45771 | C20: 846.5 | F20: 45421 | G20: 542 | Q20: 45421 | R20: 542
B21: 45778 | C21: 618.5 | F21: 45428 | G21: 619.5 | Q21: 45428 | R21: 619.5
B22: 45785 | C22: 799 | F22: 45435 | G22: 1311.5 | Q22: 45435 | R22: 1311.5
B23: 45792 | C23: 876 | F23: 45442 | G23: 484 | Q23: 45442 | R23: 484
B24: 45799 | C24: 794 | F24: 45449 | G24: 424 | Q24: 45449 | R24: 424
... B41: 45918 | C41: 506 | F41: 45568 | G41: 517 | Q41: 45568 | R41: 517
B42: 45925 | C42: 402.5
B43: 45932 | C43: 789.5
D46: Saturdays 5-9 PM 2024 | G46: Saturday total sales (2024) | J46: Date | K46: Trivia Night (Th 6-9 PM 2025) | M46: Thursday total sales (2025) | Q46: Thursday 5-9 pm (2024-2025)
D47: Date | E47: 5-9 PM sales | J47: 45659 | K47: 493.5 | M47: Date | N47: Gross Sales | Q47: Month | R47: Sales 2025 | S47: Sales 2024
D48: 45297 | E48: 362 | G48: Date | H48: Gross Sales | J48: 45666 | K48: 520.5 | M48: 45659 | N48: 2285.5 | Q48: Jan | R48: 2751.5 | S48: 1379.5 | U48: =R48/R61 -> 0.27284446
D49: 45304 | E49: 488.5 | G49: 45297 | H49: 1323.5 | J49: 45673 | K49: 601 | M49: 45666 | N49: 1583.5 | Q49: Feb | R49: 3002.5 | S49: 2575 | U49: =R49/R62 -> 0.42291711
D50: 45311 | E50: 564.5 | G50: 45304 | H50: 1120 | J50: 45680 | K50: 682.5 | M50: 45673 | N50: 1272.5 | Q50: Mar | R50: 2092.5 | S50: 2234 | U50: =R50/R63 -> 0.24950814
D51: 45318 | E51: 565.5 | G51: 45311 | H51: 1709.5 | J51: 45687 | K51: 454 | M51: 45680 | N51: 1887.5 | Q51: Apr | R51: 3387.5 | S51: 2881 | U51: =R51/R64 -> 0.3590926
D52: 45325 | E52: 621.5 | G52: 45318 | H52: 1726 | J52: 45694 | K52: 448.5 | M52: 45687 | N52: 3055.5 | Q52: May | R52: 3672.5 | S52: 3543 | U52: =R52/R65 -> 0.41127723
D53: 45332 | E53: 516.5 | G53: 45325 | H53: 1837.5 | J53: 45701 | K53: 786 | M53: 45694 | N53: 1289 | Q53: June | R53: 2818 | S53: 1520.5 | U53: =R53/R66 -> 0.44093256
D54: 45339 | E54: 1247 | G54: 45332 | H54: 1803.5 | J54: 45708 | K54: 854.5 | M54: 45701 | N54: 1727 | Q54: July | R54: 3062 | S54: 1401.5 | U54: =R54/R67 -> 0.41369993
D55: 45346 | E55: 549 | G55: 45339 | H55: 3429.5 | J55: 45715 | K55: 913.5 | M55: 45708 | N55: 2075 | Q55: Aug | R55: 2187.5 | S55: 2031.5 | U55: =R55/R68 -> 0.35981577
D56: 45353 | E56: 923.5 | G56: 45346 | H56: 2480.5 | J56: 45722 | K56: 634 | M56: 45715 | N56: 2008.5 | Q56: Sep | R56: 1777.5 | S56: 2559.5 | U56: =R56/R69 -> 0.3164219
D57: 45360 | E57: 743.5 | G57: 45353 | H57: 2368 | J57: 45729 | K57: 388 | M57: 45722 | N57: 1692.5 | Q57: Oct | R57: 789.5 | S57: 517 | U57: =R57/R70 -> 0.1743788
D58: 45367 | E58: 761 | G58: 45360 | H58: 2732.5 | J58: 45736 | K58: 530 | M58: 45729 | N58: 2188.5
...

Sheet Trivia Nights Sales Graphs
M2: Month | N2: Sales 2025 | O2: Sales 2024
M3: Jan | N3: =2751.5 -> 2751.5 | O3: 1379.5
M4: Feb | N4: 3002.5 | O4: 2575
M5: Mar | N5: 2092.5 | O5: 2234
M6: Apr | N6: 3387.5 | O6: 2881
M7: May | N7: 3672.5 | O7: 3543
M8: June | N8: 2818 | O8: 1520.5
M9: July | N9: 3062 | O9: 1401.5
M10: Aug | N10: 2187.5 | O10: 2031.5
M11: Sep | N11: 1777.5 | O11: 2559.5
M12: Oct | N12: 789.5 | O12: 517

Sheet PercentKids Eat Free Data
A1: Kids eat Free (Saturday) 5-9 PM | G1: Saturday total sales (2025)
A2: Date | B2: Kids eat free sales
A3: 45661 | B3: 517.5 | C3: JAN | D3: =SUM(B3:B6) -> 2293.5 | F3: =D3/J4 -> 0.32225657 | G3: Date | H3: Gross Sales
A4: 45668 | B4: 621 | C4: FEB | D4: =SUM(B7:B10) -> 2920.5 | F4: =D4/J5 -> 0.31625968 | G4: 45661 | H4: 2438 | I4: JAN | J4: =SUM(H4:H7) -> 7117
A5: 45675 | B5: 571.5 | C5: MAR | D5: =SUM(B11:B15) -> 5711 | F5: =D5/J6 -> 0.37287804 | G5: 45668 | H5: 1656.5 | I5: FEB | J5: =SUM(H8:H11) -> 9234.5
A6: 45682 | B6: 583.5 | C6: APR | D6: =SUM(B16:B19) -> 4334.5 | F6: =D6/J7 -> 0.38730286 | G6: 45675 | H6: 1685.5 | I6: MAR | J6: =SUM(H12:H16) -> 15316
A7: 45689 | B7: 616.5 | C7: MAY | D7: =SUM(B20:B24) -> 3451.5 | F7: =D7/J8 -> 0.28402732 | G7: 45682 | H7: 1337 | I7: APR | J7: =SUM(H17:H20) -> 11191.5
A8: 45696 | B8: 466 | C8: JUN | D8: =SUM(B25:B28) -> 2710 | F8: =D8/J9 -> 0.32658472 | G8: 45689 | H8: 1904 | I8: MAY | J8: =SUM(H21:H25) -> 12152
A9: 45703 | B9: 926 | C9: JUL | D9: =SUM(B29:B32) -> 2729 | F9: =D9/J10 -> 0.31647918 | G9: 45696 | H9: 1819.5 | I9: JUN | J9: =SUM(H26:H29) -> 8298
A10: 45710 | B10: 912 | C10: AUG | D10: =SUM(B33:B37) -> 4108.5 | F10: =D10/J11 -> 0.4068426 | G10: 45703 | H10: 2978.5 | I10: JUL | J10: =SUM(H30:H33) -> 8623
A11: 45717 | B11: 805.5 | C11: SEP | D11: =SUM(B38:B41) -> 2047.5 | F11: =D11/J12 -> 0.26038024 | G11: 45710 | H11: 2532.5 | I11: AUG | J11: =SUM(H34:H38) -> 10098.5
A12: 45724 | B12: 783 | G12: 45717 | H12: 2293 | I12: SEP | J12: =SUM(H39:H42) -> 7863.5
A13: 45731 | B13: 1286 | G13: 45724 | H13: 2720.5
A14: 45738 | B14: 1690.5 | G14: 45731 | H14: 3799.5
A15: 45745 | B15: 1146 | G15: 45738 | H15: 3780
A16: 45752 | B16: 1262 | G16: 45745 | H16: 2723
A17: 45759 | B17: 935 | G17: 45752 | H17: 2981.5
A18: 45766 | B18: 1560 | G18: 45759 | H18: 2852.5
A19: 45773 | B19: 577.5 | G19: 45766 | H19: 3116.5
A20: 45780 | B20: 517 | G20: 45773 | H20: 2241
A21: 45787 | B21: 707.5 | G21: 45780 | H21: 2241.5
A22: 45794 | B22: 748 | G22: 45787 | H22: 2350
A23: 45801 | B23: 1105 | G23: 45794 | H23: 2448
A24: 45808 | B24: 374 | G24: 45801 | H24: 3723.5
... A27: 45829 | B27: 608 | G27: 45822 | H27: 1645.5
A28: 45836 | B28: 691.5 | G28: 45829 | H28: 2298 | AA28: x
A29: 45843 | B29: 696 | G29: 45836 | H29: 2251
A30: 45850 | B30: 780 | G30: 45843 | H30: 1970
A31: 45857 | B31: 784 | G31: 45850 | H31: 1979
A32: 45864 | B32: 469 | G32: 45857 | H32: 2831.5
A33: 45871 | B33: 600.5 | G33: 45864 | H33: 1842.5
A34: 45878 | B34: 577 | G34: 45871 | H34: 1846
A35: 45885 | B35: 1225.5 | G35: 45878 | H35: 1496
A36: 45892 | B36: 900 | G36: 45885 | H36: 2512
A37: 45899 | B37: 805.5 | G37: 45892 | H37: 2031.5
A38: 45906 | B38: 462 | G38: 45899 | H38: 2213
A39: 45913 | B39: 621 | G39: 45906 | H39: 1582.5
A40: 45920 | B40: 379.5 | G40: 45913 | H40: 2359.5
... A42: 45934 | B42: 1098.5 | G42: 45927 | H42: 2253
G43: 45934 | H43: 3253
...

Sheet PercentKids Eat Free Graphs
S1: Column 1 | T1: Column 2

Sheet Grand Canyon Visits Tracker
A1: Grand Canyon NP | D1: Verde | E1: Verde
A2: Month | B2: Total Visitors | D2: Month | E2: Total Net Sales
A3: 45870 | B3: 426364 | D3: 45870 | E3: 59945.61
A4: 45839 | B4: 460018 | D4: 45839 | E4: 59708.36
A5: 45809 | B5: 459138 | D5: 45809 | E5: 57498.92
A6: 45778 | B6: 509130 | D6: 45778 | E6: 72114.71
A7: 45748 | B7: 465427 | D7: 45748 | E7: 82645.48
A8: 45717 | B8: 350734 | D8: 45717 | E8: 90759.36
A9: 45689 | B9: 207238 | D9: 45689 | E9: 60450.56
A10: 45658 | B10: 195036 | D10: 45658 | E10: 57269
A11: 45627 | B11: 321669 | D11: 45627 | E11: 61962.09
A12: 45597 | B12: 337637 | D12: 45597 | E12: 66922.81
A13: 45566 | B13: 455832 | D13: 45566 | E13: 72270.2
A14: 45536 | B14: 475720 | D14: 45536 | E14: 58070.43
... A22: 45292 | B22: 177693 | D22: 45292 | E22: 33900.14
A26: Grand Canyon Monthly Visit Statistics

Sheet Montezuma Castle Visits Tracker
A1: Month | B1: Total Visitors | D1: Month | E1: Total Net Sales
A2: 45870 | B2: 16971 | D2: 45870 | E2: 59945.61
A3: 45839 | B3: 17763 | D3: 45839 | E3: 59708.36
A4: 45809 | B4: 23289 | D4: 45809 | E4: 57498.92
A5: 45778 | B5: 30999 | D5: 45778 | E5: 72114.71
A6: 45748 | B6: 42764 | D6: 45748 | E6: 82645.48
A7: 45717 | B7: 44997 | D7: 45717 | E7: 90759.36
A8: 45689 | B8: 32189 | D8: 45689 | E8: 60450.56
A9: 45658 | B9: 25113 | D9: 45658 | E9: 57269
A10: 45627 | B10: 26539 | D10: 45627 | E10: 61962.09
A11: 45597 | B11: 29777 | D11: 45597 | E11: 66922.81
A12: 45566 | B12: 37683 | D12: 45566 | E12: 72270.2
A13: 45536 | B13: 28015 | D13: 45536 | E13: 58070.43
... A21: 45292 | B21: 22714 | D21: 45292 | E21: 33900.14
A25: Montezuma Castle Monthly Visit Statistics

Sheet Gas Prices
A2: Month | B2: Avg Gas Price | C2: Net Total Sales
A3: 44927 | B3: 3.469 | C3: 35616.27
A4: 44958 | B4: 3.577 | C4: 39872.05
A5: 44986 | B5: 4.215 | C5: 62238.99
A6: 45017 | B6: 4.796 | C6: 60765.49
A7: 45047 | B7: 4.936 | C7: 47491.77
A8: 45078 | B8: 4.389 | C8: 46379.82
A9: 45108 | B9: 3.877 | C9: 38287.07
A10: 45139 | B10: 4.27 | C10: 37317.66
A11: 45170 | B11: 4.762 | C11: 46764.38
A12: 45200 | B12: 4.492 | C12: 55486.65
A13: 45231 | B13: 3.724 | C13: 51436.32
A14: 45261 | B14: 3.318 | C14: 40688.22
A15: 45292 | B15: 3.211 | C15: 33900.14 | G15: {=TRANSPOSE(D15:D34)}
A16: 45323 | B16: 3.368 | C16: 46178.22
A17: 45352 | B17: 3.72 | C17: 61948.82
A18: 45383 | B18: 4.236 | C18: 52956.34
A19: 45413 | B19: 4.034 | C19: 58492.88
A20: 45444 | B20: 3.698 | C20: 43087.67
A21: 45474 | B21: 3.492 | C21: 38846.61 | G21: {=SORT(D15:D34,SEQUENCE(ROWS(D15:D34),1),TRUE)}
A22: 45505 | B22: 3.455 | C22: 50010.55
A23: 45536 | B23: 3.416 | C23: 58070.43
A24: 45566 | B24: 3.314 | C24: 72270.2
A25: 45597 | B25: 3.203 | C25: 66922.81
A26: 45627 | B26: 3.144 | C26: 61962.09
A27: 45658 | B27: 3.122 | C27: 57269
A28: 45689 | B28: 3.511 | C28: 60450.56
A29: 45717 | B29: 3.522 | C29: 90759.36
A30: 45748 | B30: 3.53 | C30: 82645.48
A31: 45778 | B31: 3.501 | C31: 72114.71
A32: 45809 | B32: 3.42 | C32: 57498.92
A33: 45839 | B33: 3.298 | C33: 59708.36
... A35: 45901 | B35: 3.81 | C35: 56655.82
A40: Average Price: Gasoline, Unleaded Regular (Cost per Gallon/3.785 Liters) in Phoenix-Mesa-Scottsdale, AZ (CBSA) (APUS48A74714) | FRED

Sheet Drink Sales - Pints Only
A1: October (exc Halloween) - Pints Only | F1: September - Pints Only | K1: August - Pints Only
B2: Items Sold | C2: Gross Sales | D2: % of Beer GS | G2: Items Sold | H2: Gross Sales | I2: % of Beer GS | L2: Items Sold | M2: Gross Sales | N2: % of Beer GS
A3: Bullpen Bourbon Stout | B3: 139 | C3: 1112 | D3: =C3/$C$16 -> 0.072125831 | F3: Amber Ale | G3: 104 | H3: 728 | I3: =H3/$H$18 -> 0.056177174 | K3: Amber Ale | L3: 123 | M3: 861 | N3: =M3/$M$15 -> 0.066037736
A4: Dark Lager | B4: 188 | C4: 1222 | D4: =C4/$C$16 -> 0.079260581 | F4: Bullpen Bourbon Stout | G4: 92 | H4: 736 | I4: =H4/$H$18 -> 0.056794506 | K4: Bullpen Bourbon Stout | L4: 79 | M4: 632 | N4: =M4/$M$15 -> 0.048473692
A5: Gold Buckle | B5: 294 | C5: 1911 | D5: =C5/$C$16 -> 0.12395006 | F5: Dark Lager | G5: 81 | H5: 526.5 | I5: =H5/$H$18 -> 0.040628135 | K5: Dark Lager | L5: 87 | M5: 565.5 | N5: =M5/$M$15 -> 0.043373217
A6: IPL Mosaic | B6: 220 | C6: 1760 | D6: =C6/$C$16 -> 0.11415599 | F6: Gold Buckle | G6: 594 | H6: 3861 | I6: =H6/$H$18 -> 0.29793966 | K6: Gold Buckle | L6: 549 | M6: 3568.5 | N6: =M6/$M$15 -> 0.27369995
A7: Light Lager | B7: 250 | C7: 1500 | D7: =C7/$C$16 -> 0.097292038 | F7: Hefeweizen | G7: 35 | H7: 227.5 | I7: =H7/$H$18 -> 0.017555367 | K7: Hefeweizen | L7: 117 | M7: 760.5 | N7: =M7/$M$15 -> 0.058329498
A8: Marzen | B8: 289 | C8: 2023 | D8: =C8/$C$16 -> 0.13121453 | F8: IPL Mosaic | G8: 112 | H8: 896 | I8: =H8/$H$18 -> 0.069141137 | K8: Light Lager | L8: 70 | M8: 420 | N8: =M8/$M$15 -> 0.03221353
A9: Nectaron Hazy IPA | B9: 251 | C9: 2008 | D9: =C9/$C$16 -> 0.13024161 | F9: Light Lager | G9: 61 | H9: 366 | I9: =H9/$H$18 -> 0.02824292 | K9: Nectaron Hazy IPA | L9: 151 | M9: 1208 | N9: =M9/$M$15 -> 0.092652247
A10: Redneck Rodeo | B10: 91 | C10: 728 | D10: =C10/$C$16 -> 0.047219069 | F10: Marzen | G10: 30 | H10: 210 | I10: =H10/$H$18 -> 0.016204954 | K10: Pale Ale | L10: 88 | M10: 616 | N10: =M10/$M$15 -> 0.04724651
A11: Scotch Ale | B11: 3 | C11: 21 | D11: =C11/$C$16 -> 0.0013620885 | F11: Nectaron Hazy IPA | G11: 212 | H11: 1696 | I11: =H11/$H$18 -> 0.1308743 | K11: Redneck Rodeo | L11: 112 | M11: 896 | N11: =M11/$M$15 -> 0.068722197
A12: Smokey Rye Lager | B12: 121 | C12: 847 | D12: =C12/$C$16 -> 0.054937571 | F12: Pale Ale | G12: 64 | H12: 448 | I12: =H12/$H$18 -> 0.034570569 | K12: Smokey Rye Lager | L12: 55 | M12: 385 | N12: =M12/$M$15 -> 0.029529069
A13: Stone Sour | B13: 57 | C13: 370.5 | D13: =C13/$C$16 -> 0.024031133 | F13: Redneck Rodeo | G13: 133 | H13: 1064 | I13: =H13/$H$18 -> 0.082105101 | K13: Stone Sour | L13: 103 | M13: 669.5 | N13: =M13/$M$15 -> 0.0513499
A14: Watermelon | B14: 117 | C14: 819 | D14: =C14/$C$16 -> 0.053121453 | F14: Smokey Rye Lager | G14: 69 | H14: 483 | I14: =H14/$H$18 -> 0.037271394 | K14: Wildflower IPA | L14: 307 | M14: 2456 | N14: =M14/$M$15 -> 0.18837245
A15: West Coast IPA | B15: 137 | C15: 1096 | D15: =C15/$C$16 -> 0.071088049 | F15: Stone Sour | G15: 54 | H15: 351 | I15: =H15/$H$18 -> 0.027085423 | M15: =SUM(M3:M14) -> 13038
C16: =SUM(C3:C15) -> 15417.5 | F16: Watermelon | G16: 74 | H16: 518 | I16: =H16/$H$18 -> 0.03997222
F17: Wildflower IPA | G17: 106 | H17: 848 | I17: =H17/$H$18 -> 0.065437148
H18: =SUM(H3:H17) -> 12959
A20: Beer Type | B20: October | E20: Beer Type | F20: September | H20: Beer Type | I20: August
A21: Marzen | B21: 2023 | E21: Gold Buckle | F21: 3861 | H21: Gold Buckle | I21: 3568.5
A22: Nectaron Hazy IPA | B22: 2008 | E22: Nectaron Hazy IPA | F22: 1696 | H22: Wildflower IPA | I22: 2456
A23: Gold Buckle | B23: 1911 | E23: Redneck Rodeo | F23: 1064 | H23: Nectaron Hazy IPA | I23: 1208
A24: IPL Mosaic | B24: 1760 | E24: IPL Mosaic | F24: 896 | H24: Redneck Rodeo | I24: 896
A25: Light Lager | B25: 1500 | E25: Wildflower IPA | F25: 848 | H25: Amber Ale | I25: 861
A26: Dark Lager | B26: 1222 | E26: Bullpen Bourbon Stout | F26: 736 | H26: Hefeweizen | I26: 760.5
A27: Bullpen Bourbon Stout | B27: 1112 | E27: Amber Ale | F27: 728 | H27: Stone Sour | I27: 669.5
A28: West Coast IPA | B28: 1096 | E28: Dark Lager | F28: 526.5 | H28: Bullpen Bourbon Stout | I28: 632
A29: Smokey Rye Lager | B29: 847 | E29: Watermelon | F29: 518 | H29: Pale Ale | I29: 616
A30: Watermelon | B30: 819 | E30: Smokey Rye Lager | F30: 483 | H30: Dark Lager | I30: 565.5
A31: Redneck Rodeo | B31: 728 | E31: Pale Ale | F31: 448 | H31: Light Lager | I31: 420
A32: Stone Sour | B32: 370.5 | E32: Light Lager | F32: 366 | H32: Smokey Rye Lager | I32: 385
A33: Scotch Ale | B33: 21 | E33: Stone Sour | F33: 351
B34: =SUM('Drink Sales - Pints Only'!$B$21:$B$33) -> 15417.5 | E34: Hefeweizen | F34: 227.5
E35: Marzen | F35: 210
F36: =SUM('Drink Sales - Pints Only'!$F$21:$F$35) -> 12959

Sheet Sandwich Sales
A1: October (exc Halloween) | F1: September | K1: August
B2: Items Sold | C2: Gross Sales | D2: % of Sandwich GS | G2: Items Sold | H2: Gross Sales | I2: % of Sandwich GS | L2: Items Sold | M2: Gross Sales | N2: % of Sandwich GS
A3: Chicken Sandwich | B3: 154 | C3: 2194 | D3: =C3/$C$8 -> 0.22604574 | F3: Chicken Sandwich | G3: 146 | H3: 2094 | I3: =H3/$H$8 -> 0.21187898 | K3: Chicken Sandwich | L3: 132 | M3: 1882 | N3: =M3/$M$8 -> 0.21329404
A4: Meatball Sub | B4: 62 | C4: 931 | D4: =C4/$C$8 -> 0.095920049 | F4: Meatball Sub | G4: 84 | H4: 1239 | I4: =H4/$H$8 -> 0.12536679 | K4: Meatball Sub | L4: 56 | M4: 835 | N4: =M4/$M$8 -> 0.094633649
A5: PBJ | B5: 19 | C5: 135 | D5: =C5/$C$8 -> 0.013908922 | F5: PBJ | G5: 24 | H5: 174 | I5: =H5/$H$8 -> 0.01760599 | K5: PBJ | L5: 19 | M5: 133 | N5: =M5/$M$8 -> 0.015073384
A6: Pulled Pork Sandwich | B6: 252 | C6: 3682 | D6: =C6/$C$8 -> 0.37935298 | F6: Pulled Pork Sandwich | G6: 244 | H6: 3582 | I6: =H6/$H$8 -> 0.36244055 | K6: Pulled Pork Sandwich | L6: 215 | M6: 3157.5 | N6: =M6/$M$8 -> 0.35785119
A7: Roast Beef Sandwich | B7: 171 | C7: 2764 | D7: =C7/$C$8 -> 0.28477231 | F7: Roast Beef Sandwich | G7: 174 | H7: 2794 | I7: =H7/$H$8 -> 0.28270768 | K7: Roast Beef Sandwich | L7: 175 | M7: 2816 | N7: =M7/$M$8 -> 0.31914773
C8: =SUM(C2:C7) -> 9706 | H8: =SUM(H3:H7) -> 9883 | M8: =SUM(M2:M7) -> 8823.5

Sheet Hotdog Sales
A1: October (exc Halloween) | F1: September | K1: August
B2: Items Sold | C2: Gross Sales | D2: % of Hotdog GS | G2: Items Sold | H2: Gross Sales | I2: % of Hotdog GS | L2: Items Sold | M2: Gross Sales | N2: % of Hotdog GS
A3: Chili Dog | B3: 78 | C3: 866 | D3: =C3/$C$7 -> 0.30530583 | F3: Chili Dog | G3: 54 | H3: 608 | I3: =H3/$H$7 -> 0.30453293 | K3: Chili Dog | L3: 42 | M3: 476 | N3: =M3/$M$7 -> 0.16501993
A4: Elote Dog | B4: 82 | C4: 885 | D4: =C4/$C$7 -> 0.31200423 | F4: Elote Dog | G4: 54 | H4: 577 | I4: =H4/$H$7 -> 0.28900576 | K4: Elote Dog | L4: 105 | M4: 1126.5 | N4: =M4/$M$7 -> 0.39053562
A5: Naked Dog | B5: 73 | C5: 590 | D5: =C5/$C$7 -> 0.20800282 | F5: Naked Dog | G5: 52 | H5: 418 | I5: =H5/$H$7 -> 0.20936639 | K5: Naked Dog | L5: 93 | M5: 754 | N5: =M5/$M$7 -> 0.26139712
A6: Stadium Dog | B6: 47 | C6: 495.5 | D6: =C6/$C$7 -> 0.17468711 | F6: Stadium Dog | G6: 40 | H6: 393.5 | I6: =H6/$H$7 -> 0.19709492 | K6: Stadium Dog | L6: 50 | M6: 528 | N6: =M6/$M$7 -> 0.18304732
C7: =SUM(C2:C6) -> 2836.5 | H7: =SUM(H3:H6) -> 1996.5 | M7: =SUM(M2:M6) -> 2884.5

Sheet Nacho Sales
B1: October (exc Halloween) | F1: September | K1: August
B2: Items Sold | C2: Gross Sales | D2: % of Nacho GS | G2: Items Sold | H2: Gross Sales | I2: % of Nacho GS | L2: Items Sold | M2: Gross Sales | N2: % of Nacho GS
A3: BBQ | B3: 37 | C3: 524.5 | D3: =C3/$C$8 -> 0.091368348 | F3: BBQ | G3: 22 | H3: 305 | I3: =H3/$H$8 -> 0.065394511 | K3: BBQ | L3: 32 | M3: 439.5 | N3: =M3/$M$8 -> 0.08922952
A4: Cheeseburger | B4: 29 | C4: 303.5 | D4: =C4/$C$8 -> 0.052869959 | F4: Cheeseburger | G4: 30 | H4: 333.5 | I4: =H4/$H$8 -> 0.071505146 | K4: Cheeseburger | L4: 34 | M4: 344.5 | N4: =M4/$M$8 -> 0.069942138
A5: Elote | B5: 199 | C5: 2673 | D5: =C5/$C$8 -> 0.46563888 | F5: Elote | G5: 178 | H5: 2559.5 | I5: =H5/$H$8 -> 0.54877787 | K5: Elote | L5: 169 | M5: 2331 | N5: =M5/$M$8 -> 0.47325145
A6: Spicy | B6: 68 | C6: 776 | D6: =C6/$C$8 -> 0.13517986 | F6: Spicy | G6: 49 | H6: 571.5 | I6: =H6/$H$8 -> 0.12253431 | K6: Spicy | L6: 55 | M6: 629 | N6: =M6/$M$8 -> 0.12770277
A7: Traditional | B7: 121 | C7: 1463.5 | D7: =C7/$C$8 -> 0.25494295 | F7: Traditional | G7: 72 | H7: 894.5 | I7: =H7/$H$8 -> 0.19178816 | K7: Traditional | L7: 91 | M7: 1181.5 | N7: =M7/$M$8 -> 0.23987412
C8: =SUM(C3:C7) -> 5740.5 | H8: =SUM(H2:H7) -> 4664 | M8: =SUM(M3:M7) -> 4925.5

Sheet Appetizer Sales
B1: August
B2: Units Sold
A3: Pretzle | B3: 111
A4: Elote Bowl | B4: 55
A5: Chili Bowl | B5: 33
A6: Brownie | B6: 23
A7: Guac | B7: 3
B11: September
B12: Units Sold
A13: Pretzle | B13: 99
A14: Elote Bowl | B14: 66
A15: Chili Bowl | B15: 42
A16: Brownie | B16: 25
A17: Ice Cream | B17: 1
B21: October
B22: Units Sold
A23: Pretzle | B23: 156
A24: Elote Bowl | B24: 86
A25: Chili Bowl | B25: 45
A26: Brownie | B26: 39

Sheet Customer Data
A1: Customer Name | B1: Customer # | C1: Last Visit (days ago) | D1: Visits | E1: Avg Purchase | F1: Total Spent | G1: Recency | I1: Customer Data with Purchase Count>15, containing Gold Buckle or Chili Dog
A2: Adam Reel | B2: 1 | C2: 30 | D2: 20 | E2: 47.12 | F2: 942.39 | G2: =IFS(C2<=30,"Active",C2<=364,"Cooling",TRUE,"Dormant") -> Active
A3: Andrew Ghiglieri | B3: 2 | C3: 120 | D3: 45 | E3: 44.51 | F3: 2003.02 | G3: =IFS(C3<=30,"Active",C3<=364,"Cooling",TRUE,"Dormant") -> Cooling | I3: bins (# of days)
A4: Andrew Myers | B4: 3 | C4: 60 | D4: 159 | E4: 17.43 | F4: 2771.67 | G4: =IFS(C4<=30,"Active",C4<=364,"Cooling",TRUE,"Dormant") -> Cooling | I4: 0-30 | J4: Active
A5: Ann Izard | B5: 4 | C5: 19 | D5: 32 | E5: 36.28 | F5: 1160.84 | G5: =IFS(C5<=30,"Active",C5<=364,"Cooling",TRUE,"Dormant") -> Active | I5: 31-364 | J5: Cooling
A6: Beth Mogle | B6: 5 | C6: 180 | D6: 46 | E6: 36.91 | F6: 1697.9 | G6: =IFS(C6<=30,"Active",C6<=364,"Cooling",TRUE,"Dormant") -> Cooling | I6: 365+ | J6: Dormant
A7: Brenda Dickey | B7: 6 | C7: 5 | D7: 43 | E7: 80.49 | F7: 3460.94 | G7: =IFS(C7<=30,"Active",C7<=364,"Cooling",TRUE,"Dormant") -> Active
A8: Camaron Mortillaro | B8: 7 | C8: 6 | D8: 46 | E8: 59.48 | F8: 2736.26 | G8: =IFS(C8<=30,"Active",C8<=364,"Cooling",TRUE,"Dormant") -> Active | I8: Happy Hour | J8: 2-5 Pm
A9: Charles Bryan | B9: 8 | C9: 365 | D9: 22 | E9: 64.56 | F9: 1420.41 | G9: =IFS(C9<=30,"Active",C9<=364,"Cooling",TRUE,"Dormant") -> Dormant | J9: M-F
A10: Chip Cain | B10: 9 | C10: 30 | D10: 80 | E10: 47.88 | F10: 3830.69 | G10: =IFS(C10<=30,"Active",C10<=364,"Cooling",TRUE,"Dormant") -> Active
A11: Christophe Bonnette | B11: 10 | C11: 120 | D11: 35 | E11: 30.1 | F11: 1053.66 | G11: =IFS(C11<=30,"Active",C11<=364,"Cooling",TRUE,"Dormant") -> Cooling
A12: Christopher Bonnette | B12: 11 | C12: 1095 | D12: 36 | E12: 25.49 | F12: 917.75 | G12: =IFS(C12<=30,"Active",C12<=364,"Cooling",TRUE,"Dormant") -> Dormant
A13: Clint Adams | B13: 12 | C13: 210 | D13: 30 | E13: 44.22 | F13: 1326.48 | G13: =IFS(C13<=30,"Active",C13<=364,"Cooling",TRUE,"Dormant") -> Cooling
A14: Dana Beard | B14: 13 | C14: 730 | D14: 50 | E14: 24.66 | F14: 1232.92 | G14: =IFS(C14<=30,"Active",C14<=364,"Cooling",TRUE,"Dormant") -> Dormant
A15: Debbie Krejci | B15: 14 | C15: 210 | D15: 23 | E15: 53.14 | F15: 1222.27 | G15: =IFS(C15<=30,"Active",C15<=364,"Cooling",TRUE,"Dormant") -> Cooling
A16: Deborah Moss | B16: 15 | C16: 365 | D16: 24 | E16: 86.86 | F16: 2084.56 | G16: =IFS(C16<=30,"Active",C16<=364,"Cooling",TRUE,"Dormant") -> Dormant
A17: Dick-yost Yaghlegian | B17: 16 | C17: 13 | D17: 31 | E17: 39.58 | F17: 1227.13 | G17: =IFS(C17<=30,"Active",C17<=364,"Cooling",TRUE,"Dormant") -> Active
A18: Diego Noguez | B18: 17 | C18: 30 | D18: 48 | E18: 19.88 | F18: 954.14 | G18: =IFS(C18<=30,"Active",C18<=364,"Cooling",TRUE,"Dormant") -> Active
A19: Donald Walton | B19: 18 | C19: 30 | D19: 48 | E19: 46.59 | F19: 2236.17 | G19: =IFS(C19<=30,"Active",C19<=364,"Cooling",TRUE,"Dormant") -> Active
A20: Dorothy Daniel | B20: 19 | C20: 30 | D20: 26 | E20: 31.28 | F20: 813.19 | G20: =IFS(C20<=30,"Active",C20<=364,"Cooling",TRUE,"Dormant") -> Active
A21: Gary Chenier | B21: 20 | C21: 6 | D21: 122 | E21: 44 | F21: 5368.56 | G21: =IFS(C21<=30,"Active",C21<=364,"Cooling",TRUE,"Dormant") -> Active
... A63: Travis Honanie | B63: 62 | C63: 60 | D63: 110 | E63: 52.32 | F63: 5755.29 | G63: =IFS(C63<=30,"Active",C63<=364,"Cooling",TRUE,"Dormant") -> Cooling
F64: =SUM(F2:F63) -> 199844.51

Sheet Customer Vis
